Workbook

Sheet Cover
B2: PAPA JOHN'S INTERNATIONAL, INC. (NASDAQ: PZZA)
B4: THE DEAL THAT DIED
B5: Take-private valuation, LBO returns analysis, and a post-mortem on Apollo's withdrawn $64.00 bid
B9: Valuation date | C9: 6-Aug-2026 (close following Q2 FY2026 earnings release)
B10: Current share price | C10: $27.47
B11: Apollo bid (withdrawn Nov-2025) | C11: $64.00 per share in cash
B12: Value destroyed since bid | C12: $36.53 per share / $1.2 billion of equity value
B14: THE QUESTION
C15: In October 2025 Apollo Global Management offered $64.00 per share in cash for Papa
C16: John's — roughly 13.8x the company's own FY2026 adjusted EBITDA guidance. Apollo
C17: withdrew weeks later. Ten months on, after two guidance cuts, a suspended dividend
C18: and North America comparable sales down 8.3%, the stock trades at $27.47.
C20: This model asks three questions: (1) what is PZZA worth today on fundamentals;
C21: (2) what could a sponsor actually pay and still clear a 20% IRR; and (3) what did
C22: Apollo have to believe to justify $64 — and was the market or the sponsor wrong?
B24: CONTENTS
B25: Assumptions | C25: Every input in the model. Blue cells are the only ones you should edit.
B26: Operating Model | C26: FY2025A-FY2031E revenue build from system-wide sales, units and comps.
B27: DCF | C27: WACC build, unlevered FCF, dual terminal value, WACC x exit-multiple sensitivity.
B28: Trading Comps | C28: QSR peer set. Multiples are input cells — refresh from Bloomberg/CapIQ.
B29: LBO | C29: Sources & uses, 5-year debt schedule with cash sweep, IRR / MoIC, sensitivities.
B30: Bid Bridge | C30: Decomposition of the $64 -> $27 move, and a solve for Apollo's required case.
B31: Football Field | C31: Valuation range summary across all methodologies.
B33: COLOR CONVENTION
B34: Blue text | C34: Hardcoded input or scenario lever — edit these
B35: Black text | C35: Formula calculated within the sheet
B36: Green text | C36: Link to another worksheet
B37: Yellow fill | C37: Key assumption / driver
B38: Green fill | C38: Model output
B40: SOURCES
C41: Papa John's Q2 FY2026 earnings release and Form 10-Q, filed 6-Aug-2026
C42: Papa John's Q4/FY2025 earnings release, filed 26-Feb-2026
C43: Papa John's Form 10-Q for the quarter ended 29-Mar-2026 (SEC EDGAR)
C44: Reuters / Semafor reporting on the Apollo Global Management bid, Jun-Nov 2025
B46: DISCLAIMER
C47: Prepared as an independent analytical exercise. Not investment advice, not a
C48: recommendation to buy or sell any security. Peer trading multiples are unpopulated
C49: placeholders pending a live data terminal and are labelled as such in-sheet.

Sheet Assumptions
A1: ASSUMPTIONS — every input in the model lives here
A2: US$ in millions except per-share data. BLUE = hardcoded input (edit these). BLACK = formula. Fiscal year ends late December.
A4: 1. MARKET DATA & CURRENT CAPITALIZATION
A5: Share price ($) | B5: 27.47 | H5: Close 6-Aug-2026, day of Q2'26 release (stock -7.7% intraday on the print)
A6: Diluted shares outstanding (mm) | B6: 33.1 | H6: Q2'26 10-Q: diluted weighted avg 33,129k; FY26 guidance ~33mm
A7: Equity value | B7: =B5*B6 -> 909.257
A8: Long-term debt incl. current portion | B8: 727.5 | H8: Q2'26 B/S: $715.218mm LT + $12.270mm current portion
A9: Finance lease liabilities | B9: 37.8 | H9: Q2'26 B/S: $27.711mm LT + $10.101mm current
A10: Total debt | B10: =B8+B9 -> 765.3
A11: Less: cash, equivalents & restricted cash | B11: 28.5 | H11: Q2'26 B/S: $28.490mm
A12: Net debt | B12: =B10-B11 -> 736.8
A13: Enterprise value | B13: =B7+B12 -> 1646.057
A14: EV / FY2026E adj. EBITDA | B14: =B13/B41 -> 8.8976054 | H14: Operating leases NOT capitalised — post-ASC 842 rent expense already sits in EBITDA
A16: 2. THE APOLLO BID (submitted Oct-2025, withdrawn Nov-2025)
A17: Offer price per share ($) | B17: 64 | H17: Reuters/Semafor; all-cash. Raised from ~$60 joint bid with Irth Capital (Jun-2025)
A18: Implied equity value | B18: =B17*B6 -> 2118.4
A19: Net debt at 28-Dec-2025 (bid period) | B19: 719.3 | H19: FY25 B/S: $710.4 LT + $5.0 current + $40.8 finance leases - $37.0 cash
A20: Implied enterprise value | B20: =B18+B19 -> 2837.7
A21: FY2026E adj. EBITDA guided at bid date | B21: 205 | H21: Company's ORIGINAL FY26 guidance was $200-210mm — midpoint used
A22: Implied entry EV / EBITDA | B22: =B20/B21 -> 13.842439 | H22: vs. ~7.7x average on Apollo's prior restaurant deals (CKE, Qdoba, CEC)
A23: Current price as % of offer | B23: =B5/B17 -> 0.42921875
A25: 3. SCENARIO SWITCH
A26: Active scenario (1 = Bear, 2 = Base, 3 = Bull) | B26: 2
A27: Active scenario name | B27: =INDEX($C$29:$E$29,1,$B$26) -> Base
A29: Operating driver | C29: Bear | D29: Base | E29: Bull | F29: ACTIVE
A30: North America comparable sales — FY2027E | C30: -0.04 | D30: -0.01 | E30: 0.015 | F30: =INDEX($C30:$E30,1,$B$26) -> -0.01
A31: North America comparable sales — FY2028E | C31: -0.02 | D31: 0.01 | E31: 0.03 | F31: =INDEX($C31:$E31,1,$B$26) -> 0.01
A32: North America comparable sales — FY2029E onward | C32: 0 | D32: 0.02 | E32: 0.035 | F32: =INDEX($C32:$E32,1,$B$26) -> 0.02
A33: International comparable sales — FY2027E onward | C33: 0.01 | D33: 0.025 | E33: 0.04 | F33: =INDEX($C33:$E33,1,$B$26) -> 0.025
A34: North America net unit growth (annual) | C34: -0.03 | D34: -0.01 | E34: 0.005 | F34: =INDEX($C34:$E34,1,$B$26) -> -0.01
A35: International net unit growth (annual) | C35: 0.015 | D35: 0.03 | E35: 0.045 | F35: =INDEX($C35:$E35,1,$B$26) -> 0.03
A36: Adjusted EBITDA margin — FY2031E exit | C36: 0.09 | D36: 0.115 | E36: 0.13 | F36: =INDEX($C36:$E36,1,$B$26) -> 0.115 | H36: FY2024A margin was 11.0%; FY2025A 9.7%; FY2026E 9.8%. Base case assumes a partial recovery only.
A38: 4. FY2026E ANCHOR — company guidance as revised 6-Aug-2026
A39: Adjusted EBITDA — guidance low | B39: 180 | H39: Cut from $200mm on 6-Aug-2026
A40: Adjusted EBITDA — guidance high | B40: 190 | H40: Cut from $210mm on 6-Aug-2026
A41: Adjusted EBITDA — guidance midpoint | B41: =AVERAGE(B39:B40) -> 185
A42: Adjusted D&A | B42: 72.5 | H42: Guidance $70-75mm
A43: Net interest expense | B43: 37.5 | H43: Guidance $35-40mm
A44: Capital expenditures | B44: 75 | H44: Guidance $70-80mm
A45: GAAP effective tax rate | B45: 0.32 | H45: Guidance 30-34%
...

Sheet Operating Model
A1: OPERATING MODEL — system-wide sales build
A2: US$ in millions. Revenue is built from system-wide restaurant sales, not grown off a trend line — this is a 92% franchised system, so revenue is a capture rate on a sales base the company does not own.
A4: Fiscal year | B4: FY2025A | C4: FY2026E | D4: FY2027E | E4: FY2028E | F4: FY2029E | G4: FY2030E | H4: FY2031E
A5: Projection year index | C5: 0 | D5: 1 | E5: 2 | F5: 3 | G5: 4 | H5: 5
A7: OPERATING DRIVERS
A8: North America comparable sales | C8: =Assumptions!$B$46 -> -0.07 | D8: =Assumptions!$F$30 -> -0.01 | E8: =Assumptions!$F$31 -> 0.01 | F8: =Assumptions!$F$32 -> 0.02 | G8: =Assumptions!$F$32 -> 0.02 | H8: =Assumptions!$F$32 -> 0.02 | J8: FY2026E per company guidance; FY2027E onward from the scenario switch on the Assumptions tab.
A9: International comparable sales | C9: =Assumptions!$B$47 -> 0.02 | D9: =Assumptions!$F$33 -> 0.025 | E9: =Assumptions!$F$33 -> 0.025 | F9: =Assumptions!$F$33 -> 0.025 | G9: =Assumptions!$F$33 -> 0.025 | H9: =Assumptions!$F$33 -> 0.025
A10: North America net unit growth | C10: =Assumptions!$B$48 -> -0.035 | D10: =Assumptions!$F$34 -> -0.01 | E10: =Assumptions!$F$34 -> -0.01 | F10: =Assumptions!$F$34 -> -0.01 | G10: =Assumptions!$F$34 -> -0.01 | H10: =Assumptions!$F$34 -> -0.01
A11: International net unit growth | C11: =Assumptions!$B$49 -> 0.027 | D11: =Assumptions!$F$35 -> 0.03 | E11: =Assumptions!$F$35 -> 0.03 | F11: =Assumptions!$F$35 -> 0.03 | G11: =Assumptions!$F$35 -> 0.03 | H11: =Assumptions!$F$35 -> 0.03
A12: Volume weighting on units opened / closed | C12: =Assumptions!$B$50 -> 0.3 | D12: =Assumptions!$B$50 -> 0.3 | E12: =Assumptions!$B$50 -> 0.3 | F12: =Assumptions!$B$50 -> 0.3 | G12: =Assumptions!$B$50 -> 0.3 | H12: =Assumptions!$B$50 -> 0.3
A14: SYSTEM-WIDE RESTAURANT SALES
A15: North America system-wide sales | B15: 3626 | C15: =B15*(1+C8)*(1+C10*C12) -> 3336.7721 | D15: =C15*(1+D8)*(1+D10*D12) -> 3293.4942 | E15: =D15*(1+E8)*(1+E10*E12) -> 3316.4498 | F15: =E15*(1+F8)*(1+F10*F12) -> 3372.6305 | G15: =F15*(1+G8)*(1+G10*G12) -> 3429.7629 | H15: =G15*(1+H8)*(1+H10*H12) -> 3487.863 | J15: FY2025A NA/intl split derived from Q2'26 disclosure ($850.7mm NA, $347.2mm intl) applied to reported $4.92bn global system sales
A16: International system-wide sales | B16: 1294 | C16: =B16*(1+C9)*(1+C11*C12) -> 1330.571 | D16: =C16*(1+D9)*(1+D11*D12) -> 1376.1098 | E16: =D16*(1+E9)*(1+E11*E12) -> 1423.2072 | F16: =E16*(1+F9)*(1+F11*F12) -> 1471.9164 | G16: =F16*(1+G9)*(1+G11*G12) -> 1522.2928 | H16: =G16*(1+H9)*(1+H11*H12) -> 1574.3933
A17: Global system-wide restaurant sales | B17: =SUM(B15:B16) -> 4920 | C17: =SUM(C15:C16) -> 4667.3431 | D17: =SUM(D15:D16) -> 4669.604 | E17: =SUM(E15:E16) -> 4739.657 | F17: =SUM(F15:F16) -> 4844.5469 | G17: =SUM(G15:G16) -> 4952.0556 | H17: =SUM(H15:H16) -> 5062.2563
A18: % growth | C18: =C17/B17-1 -> -0.051353021 | D18: =D17/C17-1 -> 0.0004843996 | E18: =E17/D17-1 -> 0.015001917 | F18: =F17/E17-1 -> 0.022130278 | G18: =G17/F17-1 -> 0.022191694 | H18: =H17/G17-1 -> 0.022253517 | J18: FY2026E computes to c.(5)% vs. company guidance of (2)% to (4)%. The model deliberately runs below guidance: management has cut the FY26 EBITDA range twice in six months. FY26E EBITDA is still pinned to the guided midpoint, so valuation is unaffected.
A20: RESTAURANT COUNT (period end)
A21: North America units | B21: 3553 | C21: =B21*(1+C10) -> 3428.645 | D21: =C21*(1+D10) -> 3394.3585 | E21: =D21*(1+E10) -> 3360.415 | F21: =E21*(1+F10) -> 3326.8108 | G21: =F21*(1+G10) -> 3293.5427 | H21: =G21*(1+H10) -> 3260.6073 | J21: FY2025A: 6,083 total per FY25 release; NA/intl split rolled back from the Q2'26 10-Q unit roll-forward
A22: International units | B22: 2530 | C22: =B22*(1+C11) -> 2598.31 | D22: =C22*(1+D11) -> 2676.2593 | E22: =D22*(1+E11) -> 2756.5471 | F22: =E22*(1+F11) -> 2839.2435 | G22: =F22*(1+G11) -> 2924.4208 | H22: =G22*(1+H11) -> 3012.1534
A23: Total system restaurants | B23: =SUM(B21:B22) -> 6083 | C23: =SUM(C21:C22) -> 6026.955 | D23: =SUM(D21:D22) -> 6070.6178 | E23: =SUM(E21:E22) -> 6116.962 | F23: =SUM(F21:F22) -> 6166.0543 | G23: =SUM(G21:G22) -> 6217.9635 | H23: =SUM(H21:H22) -> 6272.7607
A24: Implied North America AUV ($000) | B24: =B15/B21*1000 -> 1020.546 | C24: =C15/C21*1000 -> 973.20432 | D24: =D15/D21*1000 -> 970.2847 | E24: =E15/E21*1000 -> 986.91675 | F24: =F15/F21*1000 -> 1013.7729 | G24: =G15/G21*1000 -> 1041.3598 | H24: =H15/H21*1000 -> 1069.6974
A25: Implied International AUV ($000) | B25: =B16/B22*1000 -> 511.46245 | C25: =C16/C22*1000 -> 512.09095 | D25: =D16/D22*1000 -> 514.19151 | E25: =E16/E22*1000 -> 516.3007 | F25: =F16/F22*1000 -> 518.41853 | G25: =G16/G22*1000 -> 520.54506 | H25: =H16/H22*1000 -> 522.6803
A27: REVENUE BUILD
A28: Company-owned restaurant sales | B28: =B17*Assumptions!$B$53 -> 584.004 | C28: =C17*Assumptions!$B$53 -> 554.01363 | D28: =D17*Assumptions!$B$53 -> 554.28199 | E28: =E17*Assumptions!$B$53 -> 562.59729 | F28: =F17*Assumptions!$B$53 -> 575.04772 | G28: =G17*Assumptions!$B$53 -> 587.809 | H28: =H17*Assumptions!$B$53 -> 600.88982
A29: Franchise royalties & fees | B29: =B17*Assumptions!$B$54 -> 191.388 | C29: =C17*Assumptions!$B$54 -> 181.55965 | D29: =D17*Assumptions!$B$54 -> 181.6476 | E29: =E17*Assumptions!$B$54 -> 184.37266 | F29: =F17*Assumptions!$B$54 -> 188.45288 | G29: =G17*Assumptions!$B$54 -> 192.63496 | H29: =H17*Assumptions!$B$54 -> 196.92177
A30: Commissary revenues | B30: =B15*Assumptions!$B$55 -> 983.7338 | C30: =C15*Assumptions!$B$55 -> 905.26627 | D30: =D15*Assumptions!$B$55 -> 893.52497 | E30: =E15*Assumptions!$B$55 -> 899.75284 | F30: =F15*Assumptions!$B$55 -> 914.99465 | G30: =G15*Assumptions!$B$55 -> 930.49466 | H30: =H15*Assumptions!$B$55 -> 946.25724
A31: Other revenues | B31: =B17*Assumptions!$B$56 -> 88.068 | C31: =C17*Assumptions!$B$56 -> 83.545442 | D31: =D17*Assumptions!$B$56 -> 83.585912 | E31: =E17*Assumptions!$B$56 -> 84.83986 | F31: =F17*Assumptions!$B$56 -> 86.71739 | G31: =G17*Assumptions!$B$56 -> 88.641796 | H31: =H17*Assumptions!$B$56 -> 90.614388
A32: Advertising funds revenue | B32: =B15*Assumptions!$B$57 -> 176.2236 | C32: =C15*Assumptions!$B$57 -> 162.16712 | D32: =D15*Assumptions!$B$57 -> 160.06382 | E32: =E15*Assumptions!$B$57 -> 161.17946 | F32: =F15*Assumptions!$B$57 -> 163.90984 | G32: =G15*Assumptions!$B$57 -> 166.68647 | H32: =H15*Assumptions!$B$57 -> 169.51014
A33: Total revenues | B33: =SUM(B28:B32) -> 2023.4174 | C33: =SUM(C28:C32) -> 1886.5521 | D33: =SUM(D28:D32) -> 1873.1043 | E33: =SUM(E28:E32) -> 1892.7421 | F33: =SUM(F28:F32) -> 1929.1225 | G33: =SUM(G28:G32) -> 1966.2669 | H33: =SUM(H28:H32) -> 2004.1934
A34: % growth | C34: =C33/B33-1 -> -0.067640656 | D34: =D33/C33-1 -> -0.0071282581 | E34: =E33/D33-1 -> 0.010484103 | F34: =F33/E33-1 -> 0.019220989 | G34: =G33/F33-1 -> 0.019254568 | H34: =H33/G33-1 -> 0.019288563
A35: Memo: reported FY2025A total revenue | B35: 2065 | J35: FY2025A revenue reported as 'flat vs prior year' at $2.1bn (FY24: $2,063mm). Capture-rate build reproduces it to within c.2% — the gap is the Q4'25 refranchising of 85 units, which lowered the company-owned capture rate used here.
A36: Memo: model variance vs. reported | B36: =B33/B35-1 -> -0.020136852
A38: PROFITABILITY & UNLEVERED FREE CASH FLOW
A39: Adjusted EBITDA margin | B39: =B40/B33 -> 0.099336894 | C39: =C40/C33 -> 0.098062491 | D39: =$C$39+(Assumptions!$F$36-$C$39)*D5/5 -> 0.10144999 | E39: =$C$39+(Assumptions!$F$36-$C$39)*E5/5 -> 0.10483749 | F39: =$C$39+(Assumptions!$F$36-$C$39)*F5/5 -> 0.108225 | G39: =$C$39+(Assumptions!$F$36-$C$39)*G5/5 -> 0.1116125 | H39: =$C$39+(Assumptions!$F$36-$C$39)*H5/5 -> 0.115 | J39: FY2025A/FY2026E margin derived from reported and guided EBITDA. FY2027E+ margin is interpolated straight-line from FY2026E to the scenario exit margin, and drives EBITDA.
A40: Adjusted EBITDA | B40: 201 | C40: =Assumptions!$B$41 -> 185 | D40: =D33*D39 -> 190.02642 | E40: =E33*E39 -> 198.43034 | F40: =F33*F39 -> 208.77927 | G40: =G33*G39 -> 219.45996 | H40: =H33*H39 -> 230.48224
A42: Less: depreciation & amortisation | B42: =-B33*Assumptions!$B$58 -> -77.90157 | C42: =-C33*Assumptions!$B$58 -> -72.632257 | D42: =-D33*Assumptions!$B$58 -> -72.114515 | E42: =-E33*Assumptions!$B$58 -> -72.870571 | F42: =-F33*Assumptions!$B$58 -> -74.271216 | G42: =-G33*Assumptions!$B$58 -> -75.701276 | H42: =-H33*Assumptions!$B$58 -> -77.161444
A43: Adjusted EBIT | B43: =B40+B42 -> 123.09843 | C43: =C40+C42 -> 112.36774 | D43: =D40+D42 -> 117.9119 | E43: =E40+E42 -> 125.55977 | F43: =F40+F42 -> 134.50806 | G43: =G40+G42 -> 143.75869 | H43: =H40+H42 -> 153.32079
A44: EBIT margin | B44: =B43/B33 -> 0.060836894 | C44: =C43/C33 -> 0.059562491 | D44: =D43/D33 -> 0.062949993 | E44: =E43/E33 -> 0.066337495 | F44: =F43/F33 -> 0.069724996 | G44: =G43/G33 -> 0.073112498 | H44: =H43/H33 -> 0.0765
A45: Less: taxes on EBIT at marginal rate | B45: =-B43*Assumptions!$B$69 -> -30.774608 | C45: =-C43*Assumptions!$B$69 -> -28.091936 | D45: =-D43*Assumptions!$B$69 -> -29.477975 | E45: =-E43*Assumptions!$B$69 -> -31.389942 | F45: =-F43*Assumptions!$B$69 -> -33.627014 | G45: =-G43*Assumptions!$B$69 -> -35.939671 | H45: =-H43*Assumptions!$B$69 -> -38.330198
A46: NOPAT | B46: =B43+B45 -> 92.323823 | C46: =C43+C45 -> 84.275808 | D46: =D43+D45 -> 88.433926 | E46: =E43+E45 -> 94.169827 | F46: =F43+F45 -> 100.88104 | G46: =G43+G45 -> 107.81901 | H46: =H43+H45 -> 114.99059
A47: Plus: depreciation & amortisation | B47: =-B42 -> 77.90157 | C47: =-C42 -> 72.632257 | D47: =-D42 -> 72.114515 | E47: =-E42 -> 72.870571 | F47: =-F42 -> 74.271216 | G47: =-G42 -> 75.701276 | H47: =-H42 -> 77.161444
...

Sheet DCF
A1: DISCOUNTED CASH FLOW
A2: US$ in millions except per-share. Mid-year convention with a stub from the 6-Aug-2026 valuation date to fiscal year end. Operating leases are not capitalised (rent expense sits inside EBITDA under ASC 842).
A3: WACC BUILD
A4: Risk-free rate (10Y UST) | B4: =Assumptions!$B$63 -> 0.042
A5: Equity risk premium | B5: =Assumptions!$B$64 -> 0.05
A6: Levered beta | B6: =Assumptions!$B$65 -> 1.15
A7: Size / company-specific premium | B7: =Assumptions!$B$66 -> 0.01
A8: Cost of equity | B8: =B4+B6*B5+B7 -> 0.1095
A9: Pre-tax cost of debt | B9: =Assumptions!$B$68 -> 0.065
A10: Marginal tax rate | B10: =Assumptions!$B$69 -> 0.25
A11: After-tax cost of debt | B11: =B9*(1-B10) -> 0.04875
A12: Target debt / total capitalisation | B12: =Assumptions!$B$71 -> 0.35
A13: Target equity / total capitalisation | B13: =1-B12 -> 0.65
A14: WACC | B14: =B8*B13+B11*B12 -> 0.0882375
A16: UNLEVERED FREE CASH FLOW
A17: Fiscal year | B17: FY2026E | C17: FY2027E | D17: FY2028E | E17: FY2029E | F17: FY2030E | G17: FY2031E | H17: Total
A18: (stub)
A19: Adjusted EBITDA | B19: ='Operating Model'!C40 -> 185 | C19: ='Operating Model'!D40 -> 190.02642 | D19: ='Operating Model'!E40 -> 198.43034 | E19: ='Operating Model'!F40 -> 208.77927 | F19: ='Operating Model'!G40 -> 219.45996 | G19: ='Operating Model'!H40 -> 230.48224
A20: Unlevered free cash flow (full year) | B20: ='Operating Model'!C50 -> 96.075784 | C20: ='Operating Model'!D50 -> 87.905605 | D20: ='Operating Model'!E50 -> 90.313303 | E20: ='Operating Model'!F50 -> 95.313883 | F20: ='Operating Model'!G50 -> 102.13831 | G20: ='Operating Model'!H50 -> 109.19375
A21: Period factor (stub for part-year) | B21: =Assumptions!$B$75 -> 0.39 | C21: 1 | D21: 1 | E21: 1 | F21: 1 | G21: 1 | J21: Only 0.39 of FY2026 remains after the 6-Aug-2026 valuation date; H1'26 cash flow is already in the balance sheet.
A22: Free cash flow in period | B22: =B20*B21 -> 37.469556 | C22: =C20*C21 -> 87.905605 | D22: =D20*D21 -> 90.313303 | E22: =E20*E21 -> 95.313883 | F22: =F20*F21 -> 102.13831 | G22: =G20*G21 -> 109.19375
A23: Discount period (mid-year convention) | B23: =$B$21/2 -> 0.195 | C23: =$B$21+1-0.5 -> 0.89 | D23: =$B$21+2-0.5 -> 1.89 | E23: =$B$21+3-0.5 -> 2.89 | F23: =$B$21+4-0.5 -> 3.89 | G23: =$B$21+5-0.5 -> 4.89
A24: Discount factor | B24: =1/(1+$B$14)^B23 -> 0.98364611 | C24: =1/(1+$B$14)^C23 -> 0.92750427 | D24: =1/(1+$B$14)^D23 -> 0.85229949 | E24: =1/(1+$B$14)^E23 -> 0.78319254 | F24: =1/(1+$B$14)^F23 -> 0.71968899 | G24: =1/(1+$B$14)^G23 -> 0.66133448
A25: Present value of free cash flow | B25: =B22*B24 -> 36.856783 | C25: =C22*C24 -> 81.532824 | D25: =D22*D24 -> 76.973982 | E25: =E22*E24 -> 74.649123 | F25: =F22*F24 -> 73.507813 | G25: =G22*G24 -> 72.213595 | H25: =SUM(B25:G25) -> 415.73412
A27: TERMINAL VALUE — EXIT MULTIPLE METHOD
A28: FY2031E adjusted EBITDA | B28: =G19 -> 230.48224
A29: Terminal EV / EBITDA multiple | B29: =Assumptions!$B$73 -> 7
A30: Terminal value at FY2031 year end | B30: =B28*B29 -> 1613.3757
A31: Discount period to terminal value | B31: =$B$21+Assumptions!$B$96 -> 5.39
A32: Discount factor | B32: =1/(1+$B$14)^B31 -> 0.6339563
A33: Present value of terminal value | B33: =B30*B32 -> 1022.8097
A34: Present value of forecast free cash flow | B34: =$H$25 -> 415.73412
A35: Enterprise value | B35: =B33+B34 -> 1438.5438
A36: % of enterprise value from terminal value | B36: =B33/B35 -> 0.7110035
A37: Less: net debt | B37: =-Assumptions!$B$12 -> -736.8
A38: Equity value | B38: =B35+B37 -> 701.74379
A39: Diluted shares outstanding (mm) | B39: =Assumptions!$B$6 -> 33.1
A40: Implied value per share | B40: =B38/B39 -> 21.200719
A41: Premium / (discount) to current price | B41: =B40/Assumptions!$B$5-1 -> -0.22822283
A43: TERMINAL VALUE — PERPETUITY GROWTH METHOD (cross-check)
...

Sheet LBO
A1: LEVERAGED BUYOUT ANALYSIS
A2: US$ in millions. Transaction assumed to close 1-Jan-2027. Interest is calculated on opening balances to keep the model non-circular.
A3: TRANSACTION SUMMARY
A4: Offer price per share ($) | B4: =Assumptions!$B$79 -> 35.711
A5: Premium to current share price | B5: =Assumptions!$B$78 -> 0.3
A6: Diluted shares outstanding (mm) | B6: =Assumptions!$B$6 -> 33.1
A7: Purchase equity value | B7: =B4*B6 -> 1182.0341
A8: Plus: existing net debt | B8: =Assumptions!$B$12 -> 736.8
A9: Transaction enterprise value | B9: =B7+B8 -> 1918.8341
A10: Entry EBITDA (FY2026E) | B10: =Assumptions!$B$41 -> 185
A11: Entry EV / EBITDA | B11: =B9/B10 -> 10.372076
A13: SOURCES & USES
A14: USES
A15: Purchase of equity | B15: =B7 -> 1182.0341 | C15: =B15/$B$19 -> 0.59570177
A16: Refinancing of existing debt | B16: =Assumptions!$B$10 -> 765.3 | C16: =B16/$B$19 -> 0.38568309
A17: Financing fees | B17: =B24*Assumptions!$B$92 -> 6.9375 | C17: =B17/$B$19 -> 0.0034962452 | J17: Financing fees reference total debt raised in B25 - a deliberate forward reference, resolved by Excel on calculation.
A18: Advisory & other transaction fees | B18: =Assumptions!$B$93 -> 30 | C18: =B18/$B$19 -> 0.015118898
A19: Total uses | B19: =SUM(B15:B18) -> 1984.2716
A21: SOURCES
A22: Revolving credit facility (undrawn at close) | B22: =0 -> 0 | C22: =B22/$B$28 -> 0
A23: Term Loan B | B23: =Assumptions!$B$83*$B$10 -> 740 | C23: =B23/$B$28 -> 0.37293282
A24: Senior unsecured notes | B24: =Assumptions!$B$84*$B$10 -> 277.5 | C24: =B24/$B$28 -> 0.13984981
A25: Total debt | B25: =B22+B23+B24 -> 1017.5 | C25: =B25/$B$28 -> 0.51278263
A26: Cash from balance sheet | B26: =MAX(0,Assumptions!$B$11-Assumptions!$B$91) -> 0 | C26: =B26/$B$28 -> 0
A27: Sponsor equity | B27: =B19-B25-B26 -> 966.7716 | C27: =B27/$B$28 -> 0.48721737
A28: Total sources | B28: =B25+B26+B27 -> 1984.2716 | C28: =B28/$B$28 -> 1
A29: Check: sources less uses | B29: =B28-B19 -> 0
A30: Memo: total leverage at close (x entry EBITDA) | B30: =B25/$B$10 -> 5.5
A32: DEBT SCHEDULE & FREE CASH FLOW
A33: Fiscal year | B33: At close | C33: FY2027E | D33: FY2028E | E33: FY2029E | F33: FY2030E | G33: FY2031E
A34: Adjusted EBITDA | C34: ='Operating Model'!D40 -> 190.02642 | D34: ='Operating Model'!E40 -> 198.43034 | E34: ='Operating Model'!F40 -> 208.77927 | F34: ='Operating Model'!G40 -> 219.45996 | G34: ='Operating Model'!H40 -> 230.48224
A35: Less: capital expenditures | C35: ='Operating Model'!D48 -> -73.987619 | D35: ='Operating Model'!E48 -> -74.763313 | E35: ='Operating Model'!F48 -> -76.200338 | F35: ='Operating Model'!G48 -> -77.667543 | G35: ='Operating Model'!H48 -> -79.165638
A36: Less: increase in net working capital | C36: ='Operating Model'!D49 -> 1.344783 | D36: ='Operating Model'!E49 -> -1.9637818 | E36: ='Operating Model'!F49 -> -3.6380375 | F36: ='Operating Model'!G49 -> -3.7144419 | G36: ='Operating Model'!H49 -> -3.7926463
A37: Less: cash interest, net | C37: =-C47 -> -84.6625 | D37: =-D47 -> -82.922411 | E37: =-E47 -> -80.93171 | F37: =-F47 -> -78.502691 | G37: =-G47 -> -75.490054
A38: Less: cash taxes | C38: =-MAX(0,C34+'Operating Model'!D42-C47)*Assumptions!$B$94 -> -8.3123503 | D38: =-MAX(0,D34+'Operating Model'!E42-D47)*Assumptions!$B$94 -> -10.65934 | E38: =-MAX(0,E34+'Operating Model'!F42-E47)*Assumptions!$B$94 -> -13.394087 | F38: =-MAX(0,F34+'Operating Model'!G42-F47)*Assumptions!$B$94 -> -16.313999 | G38: =-MAX(0,G34+'Operating Model'!H42-G47)*Assumptions!$B$94 -> -19.457685
A39: Free cash flow before debt repayment | C39: =SUM(C34:C38) -> 24.40873 | D39: =SUM(D34:D38) -> 28.121495 | E39: =SUM(E34:E38) -> 34.615101 | F39: =SUM(F34:F38) -> 43.261287 | G39: =SUM(G34:G38) -> 52.576214
A40: Mandatory TLB amortisation | C40: =-MIN(C50,$B$23*Assumptions!$B$89) -> -7.4 | D40: =-MIN(D50,$B$23*Assumptions!$B$89) -> -7.4 | E40: =-MIN(E50,$B$23*Assumptions!$B$89) -> -7.4 | F40: =-MIN(F50,$B$23*Assumptions!$B$89) -> -7.4 | G40: =-MIN(G50,$B$23*Assumptions!$B$89) -> -7.4
A41: Cash sweep repayment of Term Loan B | C41: =-MIN(MAX(0,C39+C40)*Assumptions!$B$90,C50+C40) -> -12.756547 | D41: =-MIN(MAX(0,D39+D40)*Assumptions!$B$90,D50+D40) -> -15.541121 | E41: =-MIN(MAX(0,E39+E40)*Assumptions!$B$90,E50+E40) -> -20.411326 | F41: =-MIN(MAX(0,F39+F40)*Assumptions!$B$90,F50+F40) -> -26.895965 | G41: =-MIN(MAX(0,G39+G40)*Assumptions!$B$90,G50+G40) -> -33.882161
A43: DEBT BALANCES
A44: Revolver — beginning balance | C44: =B45 -> 0 | D44: =C45 -> 0 | E44: =D45 -> 0 | F44: =E45 -> 0 | G44: =F45 -> 0
...

Sheet Trading Comps
A1: TRADING COMPARABLES — QSR peer set
A2: TEMPLATE. Peer rows are deliberately blank: live multiples must come from a terminal, not from memory. Fill the BLUE cells and every multiple, median and mean below will populate. The PZZA row is live from this model and shows the expected format.
A4: Company | B4: Ticker | C4: Share price | D4: Diluted shares | E4: Equity value | F4: Net debt | G4: Enterprise value | H4: NTM adj. EBITDA | I4: EV / NTM EBITDA | J4: NTM EPS | K4: P / E
A5: Domino's Pizza | B5: DPZ | E5: =IF(C5="","",C5*D5) | G5: =IF(E5="","",E5+F5) | I5: =IF(OR(G5="",H5=""),"",G5/H5) | K5: =IF(OR(C5="",J5=""),"",C5/J5)
A6: Yum! Brands | B6: YUM | E6: =IF(C6="","",C6*D6) | G6: =IF(E6="","",E6+F6) | I6: =IF(OR(G6="",H6=""),"",G6/H6) | K6: =IF(OR(C6="",J6=""),"",C6/J6)
A7: Restaurant Brands Intl. | B7: QSR | E7: =IF(C7="","",C7*D7) | G7: =IF(E7="","",E7+F7) | I7: =IF(OR(G7="",H7=""),"",G7/H7) | K7: =IF(OR(C7="",J7=""),"",C7/J7)
A8: Wendy's | B8: WEN | E8: =IF(C8="","",C8*D8) | G8: =IF(E8="","",E8+F8) | I8: =IF(OR(G8="",H8=""),"",G8/H8) | K8: =IF(OR(C8="",J8=""),"",C8/J8)
A9: Jack in the Box | B9: JACK | E9: =IF(C9="","",C9*D9) | G9: =IF(E9="","",E9+F9) | I9: =IF(OR(G9="",H9=""),"",G9/H9) | K9: =IF(OR(C9="",J9=""),"",C9/J9)
A10: Wingstop | B10: WING | E10: =IF(C10="","",C10*D10) | G10: =IF(E10="","",E10+F10) | I10: =IF(OR(G10="",H10=""),"",G10/H10) | K10: =IF(OR(C10="",J10=""),"",C10/J10)
A11: Denny's | B11: DENN | E11: =IF(C11="","",C11*D11) | G11: =IF(E11="","",E11+F11) | I11: =IF(OR(G11="",H11=""),"",G11/H11) | K11: =IF(OR(C11="",J11=""),"",C11/J11)
A13: Median | I13: =IFERROR(MEDIAN(I5:I11),"n.a.") -> n.a. | K13: =IFERROR(MEDIAN(K5:K11),"n.a.") -> n.a.
A14: Mean | I14: =IFERROR(AVERAGE(I5:I11),"n.a.") -> n.a. | K14: =IFERROR(AVERAGE(K5:K11),"n.a.") -> n.a.
A16: Papa John's International | B16: PZZA | C16: =Assumptions!$B$5 -> 27.47 | D16: =Assumptions!$B$6 -> 33.1 | E16: =C16*D16 -> 909.257 | F16: =Assumptions!$B$12 -> 736.8 | G16: =E16+F16 -> 1646.057 | H16: ='Operating Model'!D40 -> 190.02642 | I16: =G16/H16 -> 8.6622535 | M16: NTM EBITDA for PZZA = FY2027E from the operating model. Peers should be pulled on the same NTM basis for consistency.
A17: Premium / (discount) to peer median | I17: =IFERROR(I16/I13-1,"n.a.") -> n.a.
A20: SELECTED MULTIPLE RANGE — analyst judgement, not a mechanical median
A21: PZZA should trade at a discount to DPZ and WING (negative comps, no unit growth, levered balance sheet, suspended dividend) and closer to WEN and DENN. The range below is the applied judgement.
A23: Selected EV / EBITDA — low | C23: 6
A24: Selected EV / EBITDA — midpoint | C24: 7
A25: Selected EV / EBITDA — high | C25: 8
A26: FY2027E adjusted EBITDA | C26: ='Operating Model'!D40 -> 190.02642
A28: Implied valuation | D28: Low | E28: Mid | F28: High
A29: Implied enterprise value | D29: =$C$26*$C$23 -> 1140.1585 | E29: =$C$26*$C$24 -> 1330.1849 | F29: =$C$26*$C$25 -> 1520.2113
A30: Less: net debt | D30: =-Assumptions!$B$12 -> -736.8 | E30: =-Assumptions!$B$12 -> -736.8 | F30: =-Assumptions!$B$12 -> -736.8
A31: Implied equity value | D31: =D29+D30 -> 403.3585 | E31: =E29+E30 -> 593.38492 | F31: =F29+F30 -> 783.41133
A32: Implied value per share | D32: =D31/Assumptions!$B$6 -> 12.186057 | E32: =E31/Assumptions!$B$6 -> 17.927037 | F32: =F31/Assumptions!$B$6 -> 23.668016
A33: Premium / (discount) to current | D33: =D32/Assumptions!$B$5-1 -> -0.5563867 | E33: =E32/Assumptions!$B$5-1 -> -0.34739582 | F33: =F32/Assumptions!$B$5-1 -> -0.13840495
A36: PRECEDENT TRANSACTIONS
A37: Date | B37: Target | C37: Acquirer | D37: EV ($mm) | E37: LTM EBITDA | F37: EV / EBITDA | G37: Premium
A38: Oct-2025 | B38: Papa John's (withdrawn) | C38: Apollo Global Mgmt | D38: =Assumptions!$B$20 -> 2837.7 | E38: =Assumptions!$B$21 -> 205 | F38: =D38/E38 -> 13.842439 | G38: =Assumptions!$B$17/48.2-1 -> 0.32780083 | M38: Premium measured against the $48.20 undisturbed price before the June-2025 Semafor report.
A44: Fill the blue rows from an M&A screen. Useful comparators: Apollo's own restaurant deals (CKE, Qdoba, CEC Entertainment) reportedly averaged c.7.7x EBITDA, and TriArtisan / Denny's (announced 2026) was c.$620mm including debt.

Sheet Bid Bridge
A1: BID POST-MORTEM — where $1.2 billion of equity value went
A2: Diluted share count is held constant at 33.1mm across both dates (actual at the bid date was c.33.0mm — immaterial), which makes the bridge tie exactly.
A4: 1. THEN AND NOW
B5: At the bid Oct-2025 | C5: Today 6-Aug-2026 | D5: Change
A6: Share price ($) | B6: =Assumptions!$B$17 -> 64 | C6: =Assumptions!$B$5 -> 27.47 | D6: =C6-B6 -> -36.53
A7: Diluted shares outstanding (mm) | B7: =Assumptions!$B$6 -> 33.1 | C7: =Assumptions!$B$6 -> 33.1 | D7: =C7-B7 -> 0
A8: Equity value | B8: =B6*B7 -> 2118.4 | C8: =C6*C7 -> 909.257 | D8: =C8-B8 -> -1209.143
A9: Net debt | B9: =Assumptions!$B$19 -> 719.3 | C9: =Assumptions!$B$12 -> 736.8 | D9: =C9-B9 -> 17.5
A10: Enterprise value | B10: =B8+B9 -> 2837.7 | C10: =C8+C9 -> 1646.057 | D10: =C10-B10 -> -1191.643
A11: FY2026E adj. EBITDA as guided at the time | B11: =Assumptions!$B$21 -> 205 | C11: =Assumptions!$B$41 -> 185 | D11: =C11-B11 -> -20
A12: EV / FY2026E adjusted EBITDA | B12: =B10/B11 -> 13.842439 | C12: =C10/C11 -> 8.8976054 | D12: =C12-B12 -> -4.9448336
A13: North America comparable sales | B13: (2)% FY2025A | C13: (8.3)% Q2 FY2026
A14: Quarterly dividend | B14: $0.46 per share | C14: Suspended
A16: 2. EQUITY VALUE BRIDGE — $64.00 to $27.47
B17: $mm | C17: $ per share
A18: Equity value at Apollo's $64.00 bid | B18: =$B$8 -> 2118.4 | C18: =B18/$C$7 -> 64
A19: (a) EBITDA guidance cut, held at the bid-date multiple | B19: =(C11-B11)*B12 -> -276.84878 | C19: =B19/$C$7 -> -8.3640115
A20: (b) Multiple de-rating, applied to today's EBITDA | B20: =(C12-B12)*C11 -> -914.79422 | C20: =B20/$C$7 -> -27.637288 | F20: Three quarters of the loss is multiple de-rating, not the earnings cut. The market did not just mark down the numbers — it withdrew the takeout premium embedded in the price and re-rated the business as a structurally challenged QSR.
A21: (c) Increase in net debt | B21: =-(C9-B9) -> -17.5 | C21: =B21/$C$7 -> -0.52870091
A22: (d) Rounding | B22: =$C$8-SUM(B18:B21) -> 0 | C22: =B22/$C$7 -> 0
A23: Equity value today | B23: =SUM(B18:B22) -> 909.257 | C23: =B23/$C$7 -> 27.47
A24: Check: actual equity value today | B24: =$C$8 -> 909.257 | C24: =B24/$C$7 -> 27.47
A26: 3. WHAT APOLLO HAD TO BELIEVE — reverse-engineering the $64.00 bid
A27: Applying an ordinary sponsor structure to the bid: 5.5x leverage on the EBITDA Papa John's was guiding to at the time.
A28: Entry enterprise value at $64.00 | B28: =$B$10 -> 2837.7
A29: Entry EBITDA (FY2026E as then guided) | B29: =$B$11 -> 205
A30: Total leverage (turns of entry EBITDA) | B30: =Assumptions!$B$83+Assumptions!$B$84 -> 5.5
A31: Debt raised | B31: =B29*B30 -> 1127.5
A32: Existing gross debt refinanced | B32: 756.3 | F32: FY2025 gross debt: $710.4mm long-term + $5.0mm current + $40.8mm finance leases.
A33: Financing fees | B33: =B31*Assumptions!$B$92 -> 28.1875
A34: Advisory & other transaction fees | B34: =Assumptions!$B$93 -> 30
A35: Total uses of funds | B35: =$B$8+B32+B33+B34 -> 2932.8875
A36: Sponsor equity cheque required | B36: =B35-B31 -> 1805.3875
A37: Sponsor equity as % of enterprise value | B37: =B36/B28 -> 0.63621507
A39: Target sponsor IRR | B39: =Assumptions!$B$97 -> 0.2
A40: Holding period (years) | B40: =Assumptions!$B$96 -> 5
A41: Required exit equity value | B41: =B36*(1+B39)^B40 -> 4492.3818
A42: Plus: assumed net debt at exit | B42: 700 | F42: Blue cells are the generous assumptions handed to Apollo. Loosen them further and the conclusion does not change.
A43: Required exit enterprise value | B43: =B41+B42 -> 5192.3818
A44: Assumed exit EV / EBITDA multiple | B44: 8
...

Sheet Football Field
A1: FOOTBALL FIELD — valuation summary
A2: Implied value per share. 'Range' is the plotted bar width; the chart stacks an invisible 'Low' base beneath it.
A3: SOLVE INPUTS
A4: Lower target IRR used for the LBO range | B4: 0.15
A5: Upper target IRR used for the LBO range | B5: 0.2
A7: Methodology | B7: Low | C7: Range | D7: High | E7: Midpoint
A8: DCF — exit multiple, WACC 7.8% to 9.8% | B8: =DCF!$D$59 -> 19.426934 | C8: =D8-B8 -> 3.6636945 | D8: =DCF!$D$57 -> 23.090628 | E8: =AVERAGE(B8,D8) -> 21.258781
A9: DCF — exit multiple 6.5x to 7.5x at base WACC | B9: =DCF!$C$58 -> 18.999988 | C9: =D9-B9 -> 4.4151906 | D9: =DCF!$E$58 -> 23.415179 | E9: =AVERAGE(B9,D9) -> 21.207583
A10: DCF — perpetuity growth (+/- 10%) | B10: =DCF!$B$51*0.9 -> 17.355913 | C10: =D10-B10 -> 3.8568695 | D10: =DCF!$B$51*1.1 -> 21.212782 | E10: =AVERAGE(B10,D10) -> 19.284347
A11: Trading comps — 6.0x to 8.0x FY2027E EBITDA | B11: ='Trading Comps'!$D$32 -> 12.186057 | C11: =D11-B11 -> 11.481959 | D11: ='Trading Comps'!$F$32 -> 23.668016 | E11: =AVERAGE(B11,D11) -> 17.927037
A12: LBO — maximum price at a 20% to 15% IRR | B12: =(LBO!$B$76/(1+$B$5)^Assumptions!$B$96+LBO!$B$78)/Assumptions!$B$6 -> 17.723184 | C12: =D12-B12 -> 2.6606018 | D12: =(LBO!$B$76/(1+$B$4)^Assumptions!$B$96+LBO!$B$78)/Assumptions!$B$6 -> 20.383786 | E12: =AVERAGE(B12,D12) -> 19.053485
A14: Concluded value range (min low to max high) | B14: =MIN(B8:B12) -> 12.186057 | D14: =MAX(D8:D12) -> 23.668016 | E14: =AVERAGE(B14,D14) -> 17.927037
A16: REFERENCE PRICES
A17: Current share price (6-Aug-2026) | B17: =Assumptions!$B$5 -> 27.47
A18: Apollo's withdrawn bid (Oct-2025) | B18: =Assumptions!$B$17 -> 64
A19: Undisturbed price before the June-2025 bid reports | B19: 48.2 | G19: Semafor, 11-Jun-2025: PZZA was trading around $48 when the Apollo/Irth consortium bid in the low $60s.
A21: Every methodology lands below the current $27.47 share price, and all of them land far below Apollo's $64.00. The DCF and the LBO agree from opposite directions: the intrinsic value of the cash flows and the most a leveraged buyer could rationally pay both sit in the high teens to low twenties.
